Workbook

Sheet 지역
C1: 그 외 | D1: 소개 | E1: 직영(가) | K1: 2025 | L1: 직영(가)
J2: 지역별통계 | K2: 합계 용량 / 건수 | M2: 1 | O2: 2 | Q2: 3 | S2: 4 | U2: 5 | W2: 6 | Y2: 7 | AA2: 8 | AC2: 9 | AE2: 10 | AG2: 11 | AI2: 12
B3: 전체 | C3: 전체 계약 용량 | D3: 전체 계약 건수 | E3: 마케팅 계약 용량 | F3: 마케팅 계약 건수 | G3: 소개 계약 용량 | H3: 소개 계약 건수 | J3: 경기 | K3: =IF( SUM( IFERROR(VALUE(SUBSTITUTE(M3,"kW","")),0), IFERROR(VALUE(SUBSTITUTE(O3,"kW","")),0), IFERROR(VALUE(SUBSTITUTE(Q3,"kW","")),0), IFERROR(VALUE(SUBSTITUTE(S3,"kW","")),0), IFERROR(VALUE(SUBSTITUTE(U3,"kW","")),0), IFERROR(VALUE(SUBSTITUTE(W3,"kW","")),0), IFERROR(VALUE(SUBSTITUTE(Y3,"kW","")),0), IFERROR(VALUE(SUBSTITUTE(AA3,"kW","")),0), IFERROR(VALUE(SUBSTITUTE(AC3,"kW","")),0), IFERROR(VALUE(SUBSTITUTE(AE3,"kW","")),0), IFERROR(VALUE(SUBSTITUTE(AG3,"kW","")),0), IFERROR(VALUE(SUBSTITUTE(AI3,"kW","")),0) )=0, "", SUM( IFERROR(VALUE(SUBSTITUTE(M3,"kW","")),0), IFERROR(VALUE(SUBSTITUTE(O3,"kW","")),0), IFERROR(VALUE(SUBSTITUTE(Q3,"kW","")),0), IFERROR(VALUE(SUBSTITUTE(S3,"kW","")),0), IFERROR(VALUE(SUBSTITUTE(U3,"kW","")),0), IFERROR(VALUE(SUBSTITUTE(W3,"kW","")),0), IFERROR(VALUE(SUBSTITUTE(Y3,"kW","")),0), IFERROR(VALUE(SUBSTITUTE(AA3,"kW","")),0), IFERROR(VALUE(SUBSTITUTE(AC3,"kW","")),0), IFERROR(VALUE(SUBSTITUTE(AE3,"kW","")),0), IFERROR(VALUE(SUBSTITUTE(AG3,"kW","")),0), IFERROR(VALUE(SUBSTITUTE(AI3,"kW","")),0) ) ) -> 11271.285 | L3: =IF( SUM( IFERROR(VALUE(SUBSTITUTE(N3,"건","")),0), IFERROR(VALUE(SUBSTITUTE(P3,"건","")),0), IFERROR(VALUE(SUBSTITUTE(R3,"건","")),0), IFERROR(VALUE(SUBSTITUTE(T3,"건","")),0), IFERROR(VALUE(SUBSTITUTE(V3,"건","")),0), IFERROR(VALUE(SUBSTITUTE(X3,"건","")),0), IFERROR(VALUE(SUBSTITUTE(Z3,"건","")),0), IFERROR(VALUE(SUBSTITUTE(AB3,"건","")),0), IFERROR(VALUE(SUBSTITUTE(AD3,"건","")),0), IFERROR(VALUE(SUBSTITUTE(AF3,"건","")),0), IFERROR(VALUE(SUBSTITUTE(AH3,"건","")),0), IFERROR(VALUE(SUBSTITUTE(AJ3,"건","")),0) )=0, "", SUM( IFERROR(VALUE(SUBSTITUTE(N3,"건","")),0), IFERROR(VALUE(SUBSTITUTE(P3,"건","")),0), IFERROR(VALUE(SUBSTITUTE(R3,"건","")),0), IFERROR(VALUE(SUBSTITUTE(T3,"건","")),0), IFERROR(VALUE(SUBSTITUTE(V3,"건","")),0), IFERROR(VALUE(SUBSTITUTE(X3,"건","")),0), IFERROR(VALUE(SUBSTITUTE(Z3,"건","")),0), IFERROR(VALUE(SUBSTITUTE(AB3,"건","")),0), IFERROR(VALUE(SUBSTITUTE(AD3,"건","")),0), IFERROR(VALUE(SUBSTITUTE(AF3,"건","")),0), IFERROR(VALUE(SUBSTITUTE(AH3,"건","")),0), IFERROR(VALUE(SUBSTITUTE(AJ3,"건","")),0) ) ) -> 51 | M3: =IF( SUM( SUMIFS('발전사업(A)'!$I:$I,'발전사업(A)'!$G:$G,M$2,'발전사업(A)'!$Q:$Q,$J3,'발전사업(A)'!$C:$C,$L$1), SUMIFS('자가소비(B)'!$I:$I,'자가소비(B)'!$G:$G,M$2,'자가소비(B)'!$Q:$Q,$J3,'자가소비(B)'!$C:$C,$L$1), SUMIFS('PPA 사업(C)'!$I:$I,'PPA 사업(C)'!$G:$G,M$2,'PPA 사업(C)'!$Q:$Q,$J3,'PPA 사업(C)'!$C:$C,$L$1), SUMIFS('리스사업(D)'!$I:$I,'리스사업(D)'!$G:$G,M$2,'리스사업(D)'!$Q:$Q,$J3,'리스사업(D)'!$C:$C,$L$1), SUMIFS('임대사업(E)'!$I:$I,'임대사업(E)'!$G:$G,M$2,'임대사업(E)'!$Q:$Q,$J3,'임대사업(E)'!$C:$C,$L$1), SUMIFS('환경부사업(F)'!$I:$I,'환경부사업(F)'!$G:$G,M$2,'환경부사업(F)'!$Q:$Q,$J3,'환경부사업(F)'!$C:$C,$L$1), SUMIFS('프로젝트(G)'!$I:$I,'프로젝트(G)'!$G:$G,M$2,'프로젝트(G)'!$Q:$Q,$J3,'프로젝트(G)'!$C:$C,$L$1), SUMIFS('협력사 EPC(H)'!$I:$I,'협력사 EPC(H)'!$G:$G,M$2,'협력사 EPC(H)'!$Q:$Q,$J3,'협력사 EPC(H)'!$C:$C,$L$1), SUMIFS('기타(Z)'!$I:$I,'기타(Z)'!$G:$G,M$2,'기타(Z)'!$Q:$Q,$J3,'기타(Z)'!$C:$C,$L$1) )=0, "", SUM( SUMIFS('발전사업(A)'!$I:$I,'발전사업(A)'!$G:$G,M$2,'발전사업(A)'!$Q:$Q,$J3,'발전사업(A)'!$C:$C,$L$1), SUMIFS('자가소비(B)'!$I:$I,'자가소비(B)'!$G:$G,M$2,'자가소비(B)'!$Q:$Q,$J3,'자가소비(B)'!$C:$C,$L$1), SUMIFS('PPA 사업(C)'!$I:$I,'PPA 사업(C)'!$G:$G,M$2,'PPA 사업(C)'!$Q:$Q,$J3,'PPA 사업(C)'!$C:$C,$L$1), SUMIFS('리스사업(D)'!$I:$I,'리스사업(D)'!$G:$G,M$2,'리스사업(D)'!$Q:$Q,$J3,'리스사업(D)'!$C:$C,$L$1), SUMIFS('임대사업(E)'!$I:$I,'임대사업(E)'!$G:$G,M$2,'임대사업(E)'!$Q:$Q,$J3,'임대사업(E)'!$C:$C,$L$1), SUMIFS('환경부사업(F)'!$I:$I,'환경부사업(F)'!$G:$G,M$2,'환경부사업(F)'!$Q:$Q,$J3,'환경부사업(F)'!$C:$C,$L$1), SUMIFS('프로젝트(G)'!$I:$I,'프로젝트(G)'!$G:$G,M$2,'프로젝트(G)'!$Q:$Q,$J3,'프로젝트(G)'!$C:$C,$L$1), SUMIFS('협력사 EPC(H)'!$I:$I,'협력사 EPC(H)'!$G:$G,M$2,'협력사 EPC(H)'!$Q:$Q,$J3,'협력사 EPC(H)'!$C:$C,$L$1), SUMIFS('기타(Z)'!$I:$I,'기타(Z)'!$G:$G,M$2,'기타(Z)'!$Q:$Q,$J3,'기타(Z)'!$C:$C,$L$1) ) ) | N3: =IF( SUM( COUNTIFS('발전사업(A)'!$G:$G, M$2, '발전사업(A)'!$Q:$Q, $J3, '발전사업(A)'!$C:$C, $L$1), COUNTIFS('자가소비(B)'!$G:$G, M$2, '자가소비(B)'!$Q:$Q, $J3, '자가소비(B)'!$C:$C, $L$1), COUNTIFS('PPA 사업(C)'!$G:$G, M$2, 'PPA 사업(C)'!$Q:$Q, $J3, 'PPA 사업(C)'!$C:$C, $L$1), COUNTIFS('리스사업(D)'!$G:$G, M$2, '리스사업(D)'!$Q:$Q, $J3, '리스사업(D)'!$C:$C, $L$1), COUNTIFS('임대사업(E)'!$G:$G, M$2, '임대사업(E)'!$Q:$Q, $J3, '임대사업(E)'!$C:$C, $L$1), COUNTIFS('환경부사업(F)'!$G:$G, M$2, '환경부사업(F)'!$Q:$Q, $J3, '환경부사업(F)'!$C:$C, $L$1), COUNTIFS('프로젝트(G)'!$G:$G, M$2, '프로젝트(G)'!$Q:$Q, $J3, '프로젝트(G)'!$C:$C, $L$1), COUNTIFS('협력사 EPC(H)'!$G:$G, M$2, '협력사 EPC(H)'!$Q:$Q, $J3, '협력사 EPC(H)'!$C:$C, $L$1), COUNTIFS('기타(Z)'!$G:$G, M$2, '기타(Z)'!$Q:$Q, $J3, '기타(Z)'!$C:$C, $L$1) ) = 0, "", COUNTIFS('발전사업(A)'!$G:$G, M$2, '발전사업(A)'!$Q:$Q, $J3, '발전사업(A)'!$C:$C, $L$1) + COUNTIFS('자가소비(B)'!$G:$G, M$2, '자가소비(B)'!$Q:$Q, $J3, '자가소비(B)'!$C:$C, $L$1) + COUNTIFS('PPA 사업(C)'!$G:$G, M$2, 'PPA 사업(C)'!$Q:$Q, $J3, 'PPA 사업(C)'!$C:$C, $L$1) + COUNTIFS('리스사업(D)'!$G:$G, M$2, '리스사업(D)'!$Q:$Q, $J3, '리스사업(D)'!$C:$C, $L$1) + COUNTIFS('임대사업(E)'!$G:$G, M$2, '임대사업(E)'!$Q:$Q, $J3, '임대사업(E)'!$C:$C, $L$1) + COUNTIFS('환경부사업(F)'!$G:$G, M$2, '환경부사업(F)'!$Q:$Q, $J3, '환경부사업(F)'!$C:$C, $L$1) + COUNTIFS('프로젝트(G)'!$G:$G, M$2, '프로젝트(G)'!$Q:$Q, $J3, '프로젝트(G)'!$C:$C, $L$1) + COUNTIFS('협력사 EPC(H)'!$G:$G, M$2, '협력사 EPC(H)'!$Q:$Q, $J3, '협력사 EPC(H)'!$C:$C, $L$1) + COUNTIFS('기타(Z)'!$G:$G, M$2, '기타(Z)'!$Q:$Q, $J3, '기타(Z)'!$C:$C, $L$1) ) | O3: =IF( SUM( SUMIFS('발전사업(A)'!$I:$I,'발전사업(A)'!$G:$G,O$2,'발전사업(A)'!$Q:$Q,$J3,'발전사업(A)'!$C:$C,$L$1), SUMIFS('자가소비(B)'!$I:$I,'자가소비(B)'!$G:$G,O$2,'자가소비(B)'!$Q:$Q,$J3,'자가소비(B)'!$C:$C,$L$1), SUMIFS('PPA 사업(C)'!$I:$I,'PPA 사업(C)'!$G:$G,O$2,'PPA 사업(C)'!$Q:$Q,$J3,'PPA 사업(C)'!$C:$C,$L$1), SUMIFS('리스사업(D)'!$I:$I,'리스사업(D)'!$G:$G,O$2,'리스사업(D)'!$Q:$Q,$J3,'리스사업(D)'!$C:$C,$L$1), SUMIFS('임대사업(E)'!$I:$I,'임대사업(E)'!$G:$G,O$2,'임대사업(E)'!$Q:$Q,$J3,'임대사업(E)'!$C:$C,$L$1), SUMIFS('환경부사업(F)'!$I:$I,'환경부사업(F)'!$G:$G,O$2,'환경부사업(F)'!$Q:$Q,$J3,'환경부사업(F)'!$C:$C,$L$1), SUMIFS('프로젝트(G)'!$I:$I,'프로젝트(G)'!$G:$G,O$2,'프로젝트(G)'!$Q:$Q,$J3,'프로젝트(G)'!$C:$C,$L$1), SUMIFS('협력사 EPC(H)'!$I:$I,'협력사 EPC(H)'!$G:$G,O$2,'협력사 EPC(H)'!$Q:$Q,$J3,'협력사 EPC(H)'!$C:$C,$L$1), SUMIFS('기타(Z)'!$I:$I,'기타(Z)'!$G:$G,O$2,'기타(Z)'!$Q:$Q,$J3,'기타(Z)'!$C:$C,$L$1) )=0, "", SUM( SUMIFS('발전사업(A)'!$I:$I,'발전사업(A)'!$G:$G,O$2,'발전사업(A)'!$Q:$Q,$J3,'발전사업(A)'!$C:$C,$L$1), SUMIFS('자가소비(B)'!$I:$I,'자가소비(B)'!$G:$G,O$2,'자가소비(B)'!$Q:$Q,$J3,'자가소비(B)'!$C:$C,$L$1), SUMIFS('PPA 사업(C)'!$I:$I,'PPA 사업(C)'!$G:$G,O$2,'PPA 사업(C)'!$Q:$Q,$J3,'PPA 사업(C)'!$C:$C,$L$1), SUMIFS('리스사업(D)'!$I:$I,'리스사업(D)'!$G:$G,O$2,'리스사업(D)'!$Q:$Q,$J3,'리스사업(D)'!$C:$C,$L$1), SUMIFS('임대사업(E)'!$I:$I,'임대사업(E)'!$G:$G,O$2,'임대사업(E)'!$Q:$Q,$J3,'임대사업(E)'!$C:$C,$L$1), SUMIFS('환경부사업(F)'!$I:$I,'환경부사업(F)'!$G:$G,O$2,'환경부사업(F)'!$Q:$Q,$J3,'환경부사업(F)'!$C:$C,$L$1), SUMIFS('프로젝트(G)'!$I:$I,'프로젝트(G)'!$G:$G,O$2,'프로젝트(G)'!$Q:$Q,$J3,'프로젝트(G)'!$C:$C,$L$1), SUMIFS('협력사 EPC(H)'!$I:$I,'협력사 EPC(H)'!$G:$G,O$2,'협력사 EPC(H)'!$Q:$Q,$J3,'협력사 EPC(H)'!$C:$C,$L$1), SUMIFS('기타(Z)'!$I:$I,'기타(Z)'!$G:$G,O$2,'기타(Z)'!$Q:$Q,$J3,'기타(Z)'!$C:$C,$L$1) ) ) -> 458.88 | P3: =IF( SUM( COUNTIFS('발전사업(A)'!$G:$G, O$2, '발전사업(A)'!$Q:$Q, $J3, '발전사업(A)'!$C:$C, $L$1), COUNTIFS('자가소비(B)'!$G:$G, O$2, '자가소비(B)'!$Q:$Q, $J3, '자가소비(B)'!$C:$C, $L$1), COUNTIFS('PPA 사업(C)'!$G:$G, O$2, 'PPA 사업(C)'!$Q:$Q, $J3, 'PPA 사업(C)'!$C:$C, $L$1), COUNTIFS('리스사업(D)'!$G:$G, O$2, '리스사업(D)'!$Q:$Q, $J3, '리스사업(D)'!$C:$C, $L$1), COUNTIFS('임대사업(E)'!$G:$G, O$2, '임대사업(E)'!$Q:$Q, $J3, '임대사업(E)'!$C:$C, $L$1), COUNTIFS('환경부사업(F)'!$G:$G, O$2, '환경부사업(F)'!$Q:$Q, $J3, '환경부사업(F)'!$C:$C, $L$1), COUNTIFS('프로젝트(G)'!$G:$G, O$2, '프로젝트(G)'!$Q:$Q, $J3, '프로젝트(G)'!$C:$C, $L$1), COUNTIFS('협력사 EPC(H)'!$G:$G, O$2, '협력사 EPC(H)'!$Q:$Q, $J3, '협력사 EPC(H)'!$C:$C, $L$1), COUNTIFS('기타(Z)'!$G:$G, O$2, '기타(Z)'!$Q:$Q, $J3, '기타(Z)'!$C:$C, $L$1) ) = 0, "", COUNTIFS('발전사업(A)'!$G:$G, O$2, '발전사업(A)'!$Q:$Q, $J3, '발전사업(A)'!$C:$C, $L$1) + COUNTIFS('자가소비(B)'!$G:$G, O$2, '자가소비(B)'!$Q:$Q, $J3, '자가소비(B)'!$C:$C, $L$1) + COUNTIFS('PPA 사업(C)'!$G:$G, O$2, 'PPA 사업(C)'!$Q:$Q, $J3, 'PPA 사업(C)'!$C:$C, $L$1) + COUNTIFS('리스사업(D)'!$G:$G, O$2, '리스사업(D)'!$Q:$Q, $J3, '리스사업(D)'!$C:$C, $L$1) + COUNTIFS('임대사업(E)'!$G:$G, O$2, '임대사업(E)'!$Q:$Q, $J3, '임대사업(E)'!$C:$C, $L$1) + COUNTIFS('환경부사업(F)'!$G:$G, O$2, '환경부사업(F)'!$Q:$Q, $J3, '환경부사업(F)'!$C:$C, $L$1) + COUNTIFS('프로젝트(G)'!$G:$G, O$2, '프로젝트(G)'!$Q:$Q, $J3, '프로젝트(G)'!$C:$C, $L$1) + COUNTIFS('협력사 EPC(H)'!$G:$G, O$2, '협력사 EPC(H)'!$Q:$Q, $J3, '협력사 EPC(H)'!$C:$C, $L$1) + COUNTIFS('기타(Z)'!$G:$G, O$2, '기타(Z)'!$Q:$Q, $J3, '기타(Z)'!$C:$C, $L$1) ) -> 4 | Q3: =IF( SUM( SUMIFS('발전사업(A)'!$I:$I,'발전사업(A)'!$G:$G,Q$2,'발전사업(A)'!$Q:$Q,$J3,'발전사업(A)'!$C:$C,$L$1), SUMIFS('자가소비(B)'!$I:$I,'자가소비(B)'!$G:$G,Q$2,'자가소비(B)'!$Q:$Q,$J3,'자가소비(B)'!$C:$C,$L$1), SUMIFS('PPA 사업(C)'!$I:$I,'PPA 사업(C)'!$G:$G,Q$2,'PPA 사업(C)'!$Q:$Q,$J3,'PPA 사업(C)'!$C:$C,$L$1), SUMIFS('리스사업(D)'!$I:$I,'리스사업(D)'!$G:$G,Q$2,'리스사업(D)'!$Q:$Q,$J3,'리스사업(D)'!$C:$C,$L$1), SUMIFS('임대사업(E)'!$I:$I,'임대사업(E)'!$G:$G,Q$2,'임대사업(E)'!$Q:$Q,$J3,'임대사업(E)'!$C:$C,$L$1), SUMIFS('환경부사업(F)'!$I:$I,'환경부사업(F)'!$G:$G,Q$2,'환경부사업(F)'!$Q:$Q,$J3,'환경부사업(F)'!$C:$C,$L$1), SUMIFS('프로젝트(G)'!$I:$I,'프로젝트(G)'!$G:$G,Q$2,'프로젝트(G)'!$Q:$Q,$J3,'프로젝트(G)'!$C:$C,$L$1), SUMIFS('협력사 EPC(H)'!$I:$I,'협력사 EPC(H)'!$G:$G,Q$2,'협력사 EPC(H)'!$Q:$Q,$J3,'협력사 EPC(H)'!$C:$C,$L$1), SUMIFS('기타(Z)'!$I:$I,'기타(Z)'!$G:$G,Q$2,'기타(Z)'!$Q:$Q,$J3,'기타(Z)'!$C:$C,$L$1) )=0, "", SUM( SUMIFS('발전사업(A)'!$I:$I,'발전사업(A)'!$G:$G,Q$2,'발전사업(A)'!$Q:$Q,$J3,'발전사업(A)'!$C:$C,$L$1), SUMIFS('자가소비(B)'!$I:$I,'자가소비(B)'!$G:$G,Q$2,'자가소비(B)'!$Q:$Q,$J3,'자가소비(B)'!$C:$C,$L$1), SUMIFS('PPA 사업(C)'!$I:$I,'PPA 사업(C)'!$G:$G,Q$2,'PPA 사업(C)'!$Q:$Q,$J3,'PPA 사업(C)'!$C:$C,$L$1), SUMIFS('리스사업(D)'!$I:$I,'리스사업(D)'!$G:$G,Q$2,'리스사업(D)'!$Q:$Q,$J3,'리스사업(D)'!$C:$C,$L$1), SUMIFS('임대사업(E)'!$I:$I,'임대사업(E)'!$G:$G,Q$2,'임대사업(E)'!$Q:$Q,$J3,'임대사업(E)'!$C:$C,$L$1), SUMIFS('환경부사업(F)'!$I:$I,'환경부사업(F)'!$G:$G,Q$2,'환경부사업(F)'!$Q:$Q,$J3,'환경부사업(F)'!$C:$C,$L$1), SUMIFS('프로젝트(G)'!$I:$I,'프로젝트(G)'!$G:$G,Q$2,'프로젝트(G)'!$Q:$Q,$J3,'프로젝트(G)'!$C:$C,$L$1), SUMIFS('협력사 EPC(H)'!$I:$I,'협력사 EPC(H)'!$G:$G,Q$2,'협력사 EPC(H)'!$Q:$Q,$J3,'협력사 EPC(H)'!$C:$C,$L$1), SUMIFS('기타(Z)'!$I:$I,'기타(Z)'!$G:$G,Q$2,'기타(Z)'!$Q:$Q,$J3,'기타(Z)'!$C:$C,$L$1) ) ) -> 288.64 | R3: =IF( SUM( COUNTIFS('발전사업(A)'!$G:$G, Q$2, '발전사업(A)'!$Q:$Q, $J3, '발전사업(A)'!$C:$C, $L$1), COUNTIFS('자가소비(B)'!$G:$G, Q$2, '자가소비(B)'!$Q:$Q, $J3, '자가소비(B)'!$C:$C, $L$1), COUNTIFS('PPA 사업(C)'!$G:$G, Q$2, 'PPA 사업(C)'!$Q:$Q, $J3, 'PPA 사업(C)'!$C:$C, $L$1), COUNTIFS('리스사업(D)'!$G:$G, Q$2, '리스사업(D)'!$Q:$Q, $J3, '리스사업(D)'!$C:$C, $L$1), COUNTIFS('임대사업(E)'!$G:$G, Q$2, '임대사업(E)'!$Q:$Q, $J3, '임대사업(E)'!$C:$C, $L$1), COUNTIFS('환경부사업(F)'!$G:$G, Q$2, '환경부사업(F)'!$Q:$Q, $J3, '환경부사업(F)'!$C:$C, $L$1), COUNTIFS('프로젝트(G)'!$G:$G, Q$2, '프로젝트(G)'!$Q:$Q, $J3, '프로젝트(G)'!$C:$C, $L$1), COUNTIFS('협력사 EPC(H)'!$G:$G, Q$2, '협력사 EPC(H)'!$Q:$Q, $J3, '협력사 EPC(H)'!$C:$C, $L$1), COUNTIFS('기타(Z)'!$G:$G, Q$2, '기타(Z)'!$Q:$Q, $J3, '기타(Z)'!$C:$C, $L$1) ) = 0, "", COUNTIFS('발전사업(A)'!$G:$G, Q$2, '발전사업(A)'!$Q:$Q, $J3, '발전사업(A)'!$C:$C, $L$1) + COUNTIFS('자가소비(B)'!$G:$G, Q$2, '자가소비(B)'!$Q:$Q, $J3, '자가소비(B)'!$C:$C, $L$1) + COUNTIFS('PPA 사업(C)'!$G:$G, Q$2, 'PPA 사업(C)'!$Q:$Q, $J3, 'PPA 사업(C)'!$C:$C, $L$1) + COUNTIFS('리스사업(D)'!$G:$G, Q$2, '리스사업(D)'!$Q:$Q, $J3, '리스사업(D)'!$C:$C, $L$1) + COUNTIFS('임대사업(E)'!$G:$G, Q$2, '임대사업(E)'!$Q:$Q, $J3, '임대사업(E)'!$C:$C, $L$1) + COUNTIFS('환경부사업(F)'!$G:$G, Q$2, '환경부사업(F)'!$Q:$Q, $J3, '환경부사업(F)'!$C:$C, $L$1) + COUNTIFS('프로젝트(G)'!$G:$G, Q$2, '프로젝트(G)'!$Q:$Q, $J3, '프로젝트(G)'!$C:$C, $L$1) + COUNTIFS('협력사 EPC(H)'!$G:$G, Q$2, '협력사 EPC(H)'!$Q:$Q, $J3, '협력사 EPC(H)'!$C:$C, $L$1) + COUNTIFS('기타(Z)'!$G:$G, Q$2, '기타(Z)'!$Q:$Q, $J3, '기타(Z)'!$C:$C, $L$1) ) -> 1 | S3: =IF( SUM( SUMIFS('발전사업(A)'!$I:$I,'발전사업(A)'!$G:$G,S$2,'발전사업(A)'!$Q:$Q,$J3,'발전사업(A)'!$C:$C,$L$1), SUMIFS('자가소비(B)'!$I:$I,'자가소비(B)'!$G:$G,S$2,'자가소비(B)'!$Q:$Q,$J3,'자가소비(B)'!$C:$C,$L$1), SUMIFS('PPA 사업(C)'!$I:$I,'PPA 사업(C)'!$G:$G,S$2,'PPA 사업(C)'!$Q:$Q,$J3,'PPA 사업(C)'!$C:$C,$L$1), SUMIFS('리스사업(D)'!$I:$I,'리스사업(D)'!$G:$G,S$2,'리스사업(D)'!$Q:$Q,$J3,'리스사업(D)'!$C:$C,$L$1), SUMIFS('임대사업(E)'!$I:$I,'임대사업(E)'!$G:$G,S$2,'임대사업(E)'!$Q:$Q,$J3,'임대사업(E)'!$C:$C,$L$1), SUMIFS('환경부사업(F)'!$I:$I,'환경부사업(F)'!$G:$G,S$2,'환경부사업(F)'!$Q:$Q,$J3,'환경부사업(F)'!$C:$C,$L$1), SUMIFS('프로젝트(G)'!$I:$I,'프로젝트(G)'!$G:$G,S$2,'프로젝트(G)'!$Q:$Q,$J3,'프로젝트(G)'!$C:$C,$L$1), SUMIFS('협력사 EPC(H)'!$I:$I,'협력사 EPC(H)'!$G:$G,S$2,'협력사 EPC(H)'!$Q:$Q,$J3,'협력사 EPC(H)'!$C:$C,$L$1), SUMIFS('기타(Z)'!$I:$I,'기타(Z)'!$G:$G,S$2,'기타(Z)'!$Q:$Q,$J3,'기타(Z)'!$C:$C,$L$1) )=0, "", SUM( SUMIFS('발전사업(A)'!$I:$I,'발전사업(A)'!$G:$G,S$2,'발전사업(A)'!$Q:$Q,$J3,'발전사업(A)'!$C:$C,$L$1), SUMIFS('자가소비(B)'!$I:$I,'자가소비(B)'!$G:$G,S$2,'자가소비(B)'!$Q:$Q,$J3,'자가소비(B)'!$C:$C,$L$1), SUMIFS('PPA 사업(C)'!$I:$I,'PPA 사업(C)'!$G:$G,S$2,'PPA 사업(C)'!$Q:$Q,$J3,'PPA 사업(C)'!$C:$C,$L$1), SUMIFS('리스사업(D)'!$I:$I,'리스사업(D)'!$G:$G,S$2,'리스사업(D)'!$Q:$Q,$J3,'리스사업(D)'!$C:$C,$L$1), SUMIFS('임대사업(E)'!$I:$I,'임대사업(E)'!$G:$G,S$2,'임대사업(E)'!$Q:$Q,$J3,'임대사업(E)'!$C:$C,$L$1), SUMIFS('환경부사업(F)'!$I:$I,'환경부사업(F)'!$G:$G,S$2,'환경부사업(F)'!$Q:$Q,$J3,'환경부사업(F)'!$C:$C,$L$1), SUMIFS('프로젝트(G)'!$I:$I,'프로젝트(G)'!$G:$G,S$2,'프로젝트(G)'!$Q:$Q,$J3,'프로젝트(G)'!$C:$C,$L$1), SUMIFS('협력사 EPC(H)'!$I:$I,'협력사 EPC(H)'!$G:$G,S$2,'협력사 EPC(H)'!$Q:$Q,$J3,'협력사 EPC(H)'!$C:$C,$L$1), SUMIFS('기타(Z)'!$I:$I,'기타(Z)'!$G:$G,S$2,'기타(Z)'!$Q:$Q,$J3,'기타(Z)'!$C:$C,$L$1) ) ) -> 341.12 | T3: =IF( SUM( COUNTIFS('발전사업(A)'!$G:$G, S$2, '발전사업(A)'!$Q:$Q, $J3, '발전사업(A)'!$C:$C, $L$1), COUNTIFS('자가소비(B)'!$G:$G, S$2, '자가소비(B)'!$Q:$Q, $J3, '자가소비(B)'!$C:$C, $L$1), COUNTIFS('PPA 사업(C)'!$G:$G, S$2, 'PPA 사업(C)'!$Q:$Q, $J3, 'PPA 사업(C)'!$C:$C, $L$1), COUNTIFS('리스사업(D)'!$G:$G, S$2, '리스사업(D)'!$Q:$Q, $J3, '리스사업(D)'!$C:$C, $L$1), COUNTIFS('임대사업(E)'!$G:$G, S$2, '임대사업(E)'!$Q:$Q, $J3, '임대사업(E)'!$C:$C, $L$1), COUNTIFS('환경부사업(F)'!$G:$G, S$2, '환경부사업(F)'!$Q:$Q, $J3, '환경부사업(F)'!$C:$C, $L$1), COUNTIFS('프로젝트(G)'!$G:$G, S$2, '프로젝트(G)'!$Q:$Q, $J3, '프로젝트(G)'!$C:$C, $L$1), COUNTIFS('협력사 EPC(H)'!$G:$G, S$2, '협력사 EPC(H)'!$Q:$Q, $J3, '협력사 EPC(H)'!$C:$C, $L$1), COUNTIFS('기타(Z)'!$G:$G, S$2, '기타(Z)'!$Q:$Q, $J3, '기타(Z)'!$C:$C, $L$1) ) = 0, "", COUNTIFS('발전사업(A)'!$G:$G, S$2, '발전사업(A)'!$Q:$Q, $J3, '발전사업(A)'!$C:$C, $L$1) + COUNTIFS('자가소비(B)'!$G:$G, S$2, '자가소비(B)'!$Q:$Q, $J3, '자가소비(B)'!$C:$C, $L$1) + COUNTIFS('PPA 사업(C)'!$G:$G, S$2, 'PPA 사업(C)'!$Q:$Q, $J3, 'PPA 사업(C)'!$C:$C, $L$1) + COUNTIFS('리스사업(D)'!$G:$G, S$2, '리스사업(D)'!$Q:$Q, $J3, '리스사업(D)'!$C:$C, $L$1) + COUNTIFS('임대사업(E)'!$G:$G, S$2, '임대사업(E)'!$Q:$Q, $J3, '임대사업(E)'!$C:$C, $L$1) + COUNTIFS('환경부사업(F)'!$G:$G, S$2, '환경부사업(F)'!$Q:$Q, $J3, '환경부사업(F)'!$C:$C, $L$1) + COUNTIFS('프로젝트(G)'!$G:$G, S$2, '프로젝트(G)'!$Q:$Q, $J3, '프로젝트(G)'!$C:$C, $L$1) + COUNTIFS('협력사 EPC(H)'!$G:$G, S$2, '협력사 EPC(H)'!$Q:$Q, $J3, '협력사 EPC(H)'!$C:$C, $L$1) + COUNTIFS('기타(Z)'!$G:$G, S$2, '기타(Z)'!$Q:$Q, $J3, '기타(Z)'!$C:$C, $L$1) ) -> 2 | U3: =IF( SUM( SUMIFS('발전사업(A)'!$I:$I,'발전사업(A)'!$G:$G,U$2,'발전사업(A)'!$Q:$Q,$J3,'발전사업(A)'!$C:$C,$L$1), SUMIFS('자가소비(B)'!$I:$I,'자가소비(B)'!$G:$G,U$2,'자가소비(B)'!$Q:$Q,$J3,'자가소비(B)'!$C:$C,$L$1), SUMIFS('PPA 사업(C)'!$I:$I,'PPA 사업(C)'!$G:$G,U$2,'PPA 사업(C)'!$Q:$Q,$J3,'PPA 사업(C)'!$C:$C,$L$1), SUMIFS('리스사업(D)'!$I:$I,'리스사업(D)'!$G:$G,U$2,'리스사업(D)'!$Q:$Q,$J3,'리스사업(D)'!$C:$C,$L$1), SUMIFS('임대사업(E)'!$I:$I,'임대사업(E)'!$G:$G,U$2,'임대사업(E)'!$Q:$Q,$J3,'임대사업(E)'!$C:$C,$L$1), SUMIFS('환경부사업(F)'!$I:$I,'환경부사업(F)'!$G:$G,U$2,'환경부사업(F)'!$Q:$Q,$J3,'환경부사업(F)'!$C:$C,$L$1), SUMIFS('프로젝트(G)'!$I:$I,'프로젝트(G)'!$G:$G,U$2,'프로젝트(G)'!$Q:$Q,$J3,'프로젝트(G)'!$C:$C,$L$1), SUMIFS('협력사 EPC(H)'!$I:$I,'협력사 EPC(H)'!$G:$G,U$2,'협력사 EPC(H)'!$Q:$Q,$J3,'협력사 EPC(H)'!$C:$C,$L$1), SUMIFS('기타(Z)'!$I:$I,'기타(Z)'!$G:$G,U$2,'기타(Z)'!$Q:$Q,$J3,'기타(Z)'!$C:$C,$L$1) )=0, "", SUM( SUMIFS('발전사업(A)'!$I:$I,'발전사업(A)'!$G:$G,U$2,'발전사업(A)'!$Q:$Q,$J3,'발전사업(A)'!$C:$C,$L$1), SUMIFS('자가소비(B)'!$I:$I,'자가소비(B)'!$G:$G,U$2,'자가소비(B)'!$Q:$Q,$J3,'자가소비(B)'!$C:$C,$L$1), SUMIFS('PPA 사업(C)'!$I:$I,'PPA 사업(C)'!$G:$G,U$2,'PPA 사업(C)'!$Q:$Q,$J3,'PPA 사업(C)'!$C:$C,$L$1), SUMIFS('리스사업(D)'!$I:$I,'리스사업(D)'!$G:$G,U$2,'리스사업(D)'!$Q:$Q,$J3,'리스사업(D)'!$C:$C,$L$1), SUMIFS('임대사업(E)'!$I:$I,'임대사업(E)'!$G:$G,U$2,'임대사업(E)'!$Q:$Q,$J3,'임대사업(E)'!$C:$C,$L$1), SUMIFS('환경부사업(F)'!$I:$I,'환경부사업(F)'!$G:$G,U$2,'환경부사업(F)'!$Q:$Q,$J3,'환경부사업(F)'!$C:$C,$L$1), SUMIFS('프로젝트(G)'!$I:$I,'프로젝트(G)'!$G:$G,U$2,'프로젝트(G)'!$Q:$Q,$J3,'프로젝트(G)'!$C:$C,$L$1), SUMIFS('협력사 EPC(H)'!$I:$I,'협력사 EPC(H)'!$G:$G,U$2,'협력사 EPC(H)'!$Q:$Q,$J3,'협력사 EPC(H)'!$C:$C,$L$1), SUMIFS('기타(Z)'!$I:$I,'기타(Z)'!$G:$G,U$2,'기타(Z)'!$Q:$Q,$J3,'기타(Z)'!$C:$C,$L$1) ) ) -> 2144 | V3: =IF( SUM( COUNTIFS('발전사업(A)'!$G:$G, U$2, '발전사업(A)'!$Q:$Q, $J3, '발전사업(A)'!$C:$C, $L$1), COUNTIFS('자가소비(B)'!$G:$G, U$2, '자가소비(B)'!$Q:$Q, $J3, '자가소비(B)'!$C:$C, $L$1), COUNTIFS('PPA 사업(C)'!$G:$G, U$2, 'PPA 사업(C)'!$Q:$Q, $J3, 'PPA 사업(C)'!$C:$C, $L$1), COUNTIFS('리스사업(D)'!$G:$G, U$2, '리스사업(D)'!$Q:$Q, $J3, '리스사업(D)'!$C:$C, $L$1), COUNTIFS('임대사업(E)'!$G:$G, U$2, '임대사업(E)'!$Q:$Q, $J3, '임대사업(E)'!$C:$C, $L$1), COUNTIFS('환경부사업(F)'!$G:$G, U$2, '환경부사업(F)'!$Q:$Q, $J3, '환경부사업(F)'!$C:$C, $L$1), COUNTIFS('프로젝트(G)'!$G:$G, U$2, '프로젝트(G)'!$Q:$Q, $J3, '프로젝트(G)'!$C:$C, $L$1), COUNTIFS('협력사 EPC(H)'!$G:$G, U$2, '협력사 EPC(H)'!$Q:$Q, $J3, '협력사 EPC(H)'!$C:$C, $L$1), COUNTIFS('기타(Z)'!$G:$G, U$2, '기타(Z)'!$Q:$Q, $J3, '기타(Z)'!$C:$C, $L$1) ) = 0, "", COUNTIFS('발전사업(A)'!$G:$G, U$2, '발전사업(A)'!$Q:$Q, $J3, '발전사업(A)'!$C:$C, $L$1) + COUNTIFS('자가소비(B)'!$G:$G, U$2, '자가소비(B)'!$Q:$Q, $J3, '자가소비(B)'!$C:$C, $L$1) + COUNTIFS('PPA 사업(C)'!$G:$G, U$2, 'PPA 사업(C)'!$Q:$Q, $J3, 'PPA 사업(C)'!$C:$C, $L$1) + COUNTIFS('리스사업(D)'!$G:$G, U$2, '리스사업(D)'!$Q:$Q, $J3, '리스사업(D)'!$C:$C, $L$1) + COUNTIFS('임대사업(E)'!$G:$G, U$2, '임대사업(E)'!$Q:$Q, $J3, '임대사업(E)'!$C:$C, $L$1) + COUNTIFS('환경부사업(F)'!$G:$G, U$2, '환경부사업(F)'!$Q:$Q, $J3, '환경부사업(F)'!$C:$C, $L$1) + COUNTIFS('프로젝트(G)'!$G:$G, U$2, '프로젝트(G)'!$Q:$Q, $J3, '프로젝트(G)'!$C:$C, $L$1) + COUNTIFS('협력사 EPC(H)'!$G:$G, U$2, '협력사 EPC(H)'!$Q:$Q, $J3, '협력사 EPC(H)'!$C:$C, $L$1) + COUNTIFS('기타(Z)'!$G:$G, U$2, '기타(Z)'!$Q:$Q, $J3, '기타(Z)'!$C:$C, $L$1) ) -> 7 | W3: =IF( SUM( SUMIFS('발전사업(A)'!$I:$I,'발전사업(A)'!$G:$G,W$2,'발전사업(A)'!$Q:$Q,$J3,'발전사업(A)'!$C:$C,$L$1), SUMIFS('자가소비(B)'!$I:$I,'자가소비(B)'!$G:$G,W$2,'자가소비(B)'!$Q:$Q,$J3,'자가소비(B)'!$C:$C,$L$1), SUMIFS('PPA 사업(C)'!$I:$I,'PPA 사업(C)'!$G:$G,W$2,'PPA 사업(C)'!$Q:$Q,$J3,'PPA 사업(C)'!$C:$C,$L$1), SUMIFS('리스사업(D)'!$I:$I,'리스사업(D)'!$G:$G,W$2,'리스사업(D)'!$Q:$Q,$J3,'리스사업(D)'!$C:$C,$L$1), SUMIFS('임대사업(E)'!$I:$I,'임대사업(E)'!$G:$G,W$2,'임대사업(E)'!$Q:$Q,$J3,'임대사업(E)'!$C:$C,$L$1), SUMIFS('환경부사업(F)'!$I:$I,'환경부사업(F)'!$G:$G,W$2,'환경부사업(F)'!$Q:$Q,$J3,'환경부사업(F)'!$C:$C,$L$1), SUMIFS('프로젝트(G)'!$I:$I,'프로젝트(G)'!$G:$G,W$2,'프로젝트(G)'!$Q:$Q,$J3,'프로젝트(G)'!$C:$C,$L$1), SUMIFS('협력사 EPC(H)'!$I:$I,'협력사 EPC(H)'!$G:$G,W$2,'협력사 EPC(H)'!$Q:$Q,$J3,'협력사 EPC(H)'!$C:$C,$L$1), SUMIFS('기타(Z)'!$I:$I,'기타(Z)'!$G:$G,W$2,'기타(Z)'!$Q:$Q,$J3,'기타(Z)'!$C:$C,$L$1) )=0, "", SUM( SUMIFS('발전사업(A)'!$I:$I,'발전사업(A)'!$G:$G,W$2,'발전사업(A)'!$Q:$Q,$J3,'발전사업(A)'!$C:$C,$L$1), SUMIFS('자가소비(B)'!$I:$I,'자가소비(B)'!$G:$G,W$2,'자가소비(B)'!$Q:$Q,$J3,'자가소비(B)'!$C:$C,$L$1), SUMIFS('PPA 사업(C)'!$I:$I,'PPA 사업(C)'!$G:$G,W$2,'PPA 사업(C)'!$Q:$Q,$J3,'PPA 사업(C)'!$C:$C,$L$1), SUMIFS('리스사업(D)'!$I:$I,'리스사업(D)'!$G:$G,W$2,'리스사업(D)'!$Q:$Q,$J3,'리스사업(D)'!$C:$C,$L$1), SUMIFS('임대사업(E)'!$I:$I,'임대사업(E)'!$G:$G,W$2,'임대사업(E)'!$Q:$Q,$J3,'임대사업(E)'!$C:$C,$L$1), SUMIFS('환경부사업(F)'!$I:$I,'환경부사업(F)'!$G:$G,W$2,'환경부사업(F)'!$Q:$Q,$J3,'환경부사업(F)'!$C:$C,$L$1), SUMIFS('프로젝트(G)'!$I:$I,'프로젝트(G)'!$G:$G,W$2,'프로젝트(G)'!$Q:$Q,$J3,'프로젝트(G)'!$C:$C,$L$1), SUMIFS('협력사 EPC(H)'!$I:$I,'협력사 EPC(H)'!$G:$G,W$2,'협력사 EPC(H)'!$Q:$Q,$J3,'협력사 EPC(H)'!$C:$C,$L$1), SUMIFS('기타(Z)'!$I:$I,'기타(Z)'!$G:$G,W$2,'기타(Z)'!$Q:$Q,$J3,'기타(Z)'!$C:$C,$L$1) ) ) -> 1667.84 | X3: =IF( SUM( COUNTIFS('발전사업(A)'!$G:$G,W$2,'발전사업(A)'!$Q:$Q,$J3), COUNTIFS('자가소비(B)'!$G:$G,W$2,'자가소비(B)'!$Q:$Q,$J3), COUNTIFS('PPA 사업(C)'!$G:$G,W$2,'PPA 사업(C)'!$Q:$Q,$J3), COUNTIFS('리스사업(D)'!$G:$G,W$2,'리스사업(D)'!$Q:$Q,$J3), COUNTIFS('임대사업(E)'!$G:$G,W$2,'임대사업(E)'!$Q:$Q,$J3), COUNTIFS('환경부사업(F)'!$G:$G,W$2,'환경부사업(F)'!$Q:$Q,$J3), COUNTIFS('프로젝트(G)'!$G:$G,W$2,'프로젝트(G)'!$Q:$Q,$J3), COUNTIFS('협력사 EPC(H)'!$G:$G,W$2,'협력사 EPC(H)'!$Q:$Q,$J3), COUNTIFS('기타(Z)'!$G:$G,W$2,'기타(Z)'!$Q:$Q,$J3) )=0, "", COUNTIFS('발전사업(A)'!$G:$G,W$2,'발전사업(A)'!$Q:$Q,$J3) +COUNTIFS('자가소비(B)'!$G:$G,W$2,'자가소비(B)'!$Q:$Q,$J3) +COUNTIFS('PPA 사업(C)'!$G:$G,W$2,'PPA 사업(C)'!$Q:$Q,$J3) +COUNTIFS('리스사업(D)'!$G:$G,W$2,'리스사업(D)'!$Q:$Q,$J3) +COUNTIFS('임대사업(E)'!$G:$G,W$2,'임대사업(E)'!$Q:$Q,$J3) +COUNTIFS('환경부사업(F)'!$G:$G,W$2,'환경부사업(F)'!$Q:$Q,$J3) +COUNTIFS('프로젝트(G)'!$G:$G,W$2,'프로젝트(G)'!$Q:$Q,$J3) +COUNTIFS('협력사 EPC(H)'!$G:$G,W$2,'협력사 EPC(H)'!$Q:$Q,$J3) +COUNTIFS('기타(Z)'!$G:$G,W$2,'기타(Z)'!$Q:$Q,$J3) ) -> 7 | Y3: =IF( SUM( SUMIFS('발전사업(A)'!$I:$I,'발전사업(A)'!$G:$G,Y$2,'발전사업(A)'!$Q:$Q,$J3,'발전사업(A)'!$C:$C,$L$1), SUMIFS('자가소비(B)'!$I:$I,'자가소비(B)'!$G:$G,Y$2,'자가소비(B)'!$Q:$Q,$J3,'자가소비(B)'!$C:$C,$L$1), SUMIFS('PPA 사업(C)'!$I:$I,'PPA 사업(C)'!$G:$G,Y$2,'PPA 사업(C)'!$Q:$Q,$J3,'PPA 사업(C)'!$C:$C,$L$1), SUMIFS('리스사업(D)'!$I:$I,'리스사업(D)'!$G:$G,Y$2,'리스사업(D)'!$Q:$Q,$J3,'리스사업(D)'!$C:$C,$L$1), SUMIFS('임대사업(E)'!$I:$I,'임대사업(E)'!$G:$G,Y$2,'임대사업(E)'!$Q:$Q,$J3,'임대사업(E)'!$C:$C,$L$1), SUMIFS('환경부사업(F)'!$I:$I,'환경부사업(F)'!$G:$G,Y$2,'환경부사업(F)'!$Q:$Q,$J3,'환경부사업(F)'!$C:$C,$L$1), SUMIFS('프로젝트(G)'!$I:$I,'프로젝트(G)'!$G:$G,Y$2,'프로젝트(G)'!$Q:$Q,$J3,'프로젝트(G)'!$C:$C,$L$1), SUMIFS('협력사 EPC(H)'!$I:$I,'협력사 EPC(H)'!$G:$G,Y$2,'협력사 EPC(H)'!$Q:$Q,$J3,'협력사 EPC(H)'!$C:$C,$L$1), SUMIFS('기타(Z)'!$I:$I,'기타(Z)'!$G:$G,Y$2,'기타(Z)'!$Q:$Q,$J3,'기타(Z)'!$C:$C,$L$1) )=0, "", SUM( SUMIFS('발전사업(A)'!$I:$I,'발전사업(A)'!$G:$G,Y$2,'발전사업(A)'!$Q:$Q,$J3,'발전사업(A)'!$C:$C,$L$1), SUMIFS('자가소비(B)'!$I:$I,'자가소비(B)'!$G:$G,Y$2,'자가소비(B)'!$Q:$Q,$J3,'자가소비(B)'!$C:$C,$L$1), SUMIFS('PPA 사업(C)'!$I:$I,'PPA 사업(C)'!$G:$G,Y$2,'PPA 사업(C)'!$Q:$Q,$J3,'PPA 사업(C)'!$C:$C,$L$1), SUMIFS('리스사업(D)'!$I:$I,'리스사업(D)'!$G:$G,Y$2,'리스사업(D)'!$Q:$Q,$J3,'리스사업(D)'!$C:$C,$L$1), SUMIFS('임대사업(E)'!$I:$I,'임대사업(E)'!$G:$G,Y$2,'임대사업(E)'!$Q:$Q,$J3,'임대사업(E)'!$C:$C,$L$1), SUMIFS('환경부사업(F)'!$I:$I,'환경부사업(F)'!$G:$G,Y$2,'환경부사업(F)'!$Q:$Q,$J3,'환경부사업(F)'!$C:$C,$L$1), SUMIFS('프로젝트(G)'!$I:$I,'프로젝트(G)'!$G:$G,Y$2,'프로젝트(G)'!$Q:$Q,$J3,'프로젝트(G)'!$C:$C,$L$1), SUMIFS('협력사 EPC(H)'!$I:$I,'협력사 EPC(H)'!$G:$G,Y$2,'협력사 EPC(H)'!$Q:$Q,$J3,'협력사 EPC(H)'!$C:$C,$L$1), SUMIFS('기타(Z)'!$I:$I,'기타(Z)'!$G:$G,Y$2,'기타(Z)'!$Q:$Q,$J3,'기타(Z)'!$C:$C,$L$1) ) ) -> 927.36 | Z3: =IF( SUM( COUNTIFS('발전사업(A)'!$G:$G, Y$2, '발전사업(A)'!$Q:$Q, $J3, '발전사업(A)'!$C:$C, $L$1), COUNTIFS('자가소비(B)'!$G:$G, Y$2, '자가소비(B)'!$Q:$Q, $J3, '자가소비(B)'!$C:$C, $L$1), COUNTIFS('PPA 사업(C)'!$G:$G, Y$2, 'PPA 사업(C)'!$Q:$Q, $J3, 'PPA 사업(C)'!$C:$C, $L$1), COUNTIFS('리스사업(D)'!$G:$G, Y$2, '리스사업(D)'!$Q:$Q, $J3, '리스사업(D)'!$C:$C, $L$1), COUNTIFS('임대사업(E)'!$G:$G, Y$2, '임대사업(E)'!$Q:$Q, $J3, '임대사업(E)'!$C:$C, $L$1), COUNTIFS('환경부사업(F)'!$G:$G, Y$2, '환경부사업(F)'!$Q:$Q, $J3, '환경부사업(F)'!$C:$C, $L$1), COUNTIFS('프로젝트(G)'!$G:$G, Y$2, '프로젝트(G)'!$Q:$Q, $J3, '프로젝트(G)'!$C:$C, $L$1), COUNTIFS('협력사 EPC(H)'!$G:$G, Y$2, '협력사 EPC(H)'!$Q:$Q, $J3, '협력사 EPC(H)'!$C:$C, $L$1), COUNTIFS('기타(Z)'!$G:$G, Y$2, '기타(Z)'!$Q:$Q, $J3, '기타(Z)'!$C:$C, $L$1) ) = 0, "", COUNTIFS('발전사업(A)'!$G:$G, Y$2, '발전사업(A)'!$Q:$Q, $J3, '발전사업(A)'!$C:$C, $L$1) + COUNTIFS('자가소비(B)'!$G:$G, Y$2, '자가소비(B)'!$Q:$Q, $J3, '자가소비(B)'!$C:$C, $L$1) + COUNTIFS('PPA 사업(C)'!$G:$G, Y$2, 'PPA 사업(C)'!$Q:$Q, $J3, 'PPA 사업(C)'!$C:$C, $L$1) + COUNTIFS('리스사업(D)'!$G:$G, Y$2, '리스사업(D)'!$Q:$Q, $J3, '리스사업(D)'!$C:$C, $L$1) + COUNTIFS('임대사업(E)'!$G:$G, Y$2, '임대사업(E)'!$Q:$Q, $J3, '임대사업(E)'!$C:$C, $L$1) + COUNTIFS('환경부사업(F)'!$G:$G, Y$2, '환경부사업(F)'!$Q:$Q, $J3, '환경부사업(F)'!$C:$C, $L$1) + COUNTIFS('프로젝트(G)'!$G:$G, Y$2, '프로젝트(G)'!$Q:$Q, $J3, '프로젝트(G)'!$C:$C, $L$1) + COUNTIFS('협력사 EPC(H)'!$G:$G, Y$2, '협력사 EPC(H)'!$Q:$Q, $J3, '협력사 EPC(H)'!$C:$C, $L$1) + COUNTIFS('기타(Z)'!$G:$G, Y$2, '기타(Z)'!$Q:$Q, $J3, '기타(Z)'!$C:$C, $L$1) ) -> 3 | AA3: =IF( SUM( SUMIFS('발전사업(A)'!$I:$I,'발전사업(A)'!$G:$G,AA$2,'발전사업(A)'!$Q:$Q,$J3,'발전사업(A)'!$C:$C,$L$1), SUMIFS('자가소비(B)'!$I:$I,'자가소비(B)'!$G:$G,AA$2,'자가소비(B)'!$Q:$Q,$J3,'자가소비(B)'!$C:$C,$L$1), SUMIFS('PPA 사업(C)'!$I:$I,'PPA 사업(C)'!$G:$G,AA$2,'PPA 사업(C)'!$Q:$Q,$J3,'PPA 사업(C)'!$C:$C,$L$1), SUMIFS('리스사업(D)'!$I:$I,'리스사업(D)'!$G:$G,AA$2,'리스사업(D)'!$Q:$Q,$J3,'리스사업(D)'!$C:$C,$L$1), SUMIFS('임대사업(E)'!$I:$I,'임대사업(E)'!$G:$G,AA$2,'임대사업(E)'!$Q:$Q,$J3,'임대사업(E)'!$C:$C,$L$1), SUMIFS('환경부사업(F)'!$I:$I,'환경부사업(F)'!$G:$G,AA$2,'환경부사업(F)'!$Q:$Q,$J3,'환경부사업(F)'!$C:$C,$L$1), SUMIFS('프로젝트(G)'!$I:$I,'프로젝트(G)'!$G:$G,AA$2,'프로젝트(G)'!$Q:$Q,$J3,'프로젝트(G)'!$C:$C,$L$1), SUMIFS('협력사 EPC(H)'!$I:$I,'협력사 EPC(H)'!$G:$G,AA$2,'협력사 EPC(H)'!$Q:$Q,$J3,'협력사 EPC(H)'!$C:$C,$L$1), SUMIFS('기타(Z)'!$I:$I,'기타(Z)'!$G:$G,AA$2,'기타(Z)'!$Q:$Q,$J3,'기타(Z)'!$C:$C,$L$1) )=0, "", SUM( SUMIFS('발전사업(A)'!$I:$I,'발전사업(A)'!$G:$G,AA$2,'발전사업(A)'!$Q:$Q,$J3,'발전사업(A)'!$C:$C,$L$1), SUMIFS('자가소비(B)'!$I:$I,'자가소비(B)'!$G:$G,AA$2,'자가소비(B)'!$Q:$Q,$J3,'자가소비(B)'!$C:$C,$L$1), SUMIFS('PPA 사업(C)'!$I:$I,'PPA 사업(C)'!$G:$G,AA$2,'PPA 사업(C)'!$Q:$Q,$J3,'PPA 사업(C)'!$C:$C,$L$1), SUMIFS('리스사업(D)'!$I:$I,'리스사업(D)'!$G:$G,AA$2,'리스사업(D)'!$Q:$Q,$J3,'리스사업(D)'!$C:$C,$L$1), SUMIFS('임대사업(E)'!$I:$I,'임대사업(E)'!$G:$G,AA$2,'임대사업(E)'!$Q:$Q,$J3,'임대사업(E)'!$C:$C,$L$1), SUMIFS('환경부사업(F)'!$I:$I,'환경부사업(F)'!$G:$G,AA$2,'환경부사업(F)'!$Q:$Q,$J3,'환경부사업(F)'!$C:$C,$L$1), SUMIFS('프로젝트(G)'!$I:$I,'프로젝트(G)'!$G:$G,AA$2,'프로젝트(G)'!$Q:$Q,$J3,'프로젝트(G)'!$C:$C,$L$1), SUMIFS('협력사 EPC(H)'!$I:$I,'협력사 EPC(H)'!$G:$G,AA$2,'협력사 EPC(H)'!$Q:$Q,$J3,'협력사 EPC(H)'!$C:$C,$L$1), SUMIFS('기타(Z)'!$I:$I,'기타(Z)'!$G:$G,AA$2,'기타(Z)'!$Q:$Q,$J3,'기타(Z)'!$C:$C,$L$1) ) ) -> 377.335 | AB3: =IF( SUM( COUNTIFS('발전사업(A)'!$G:$G, AA$2, '발전사업(A)'!$Q:$Q, $J3, '발전사업(A)'!$C:$C, $L$1), COUNTIFS('자가소비(B)'!$G:$G, AA$2, '자가소비(B)'!$Q:$Q, $J3, '자가소비(B)'!$C:$C, $L$1), COUNTIFS('PPA 사업(C)'!$G:$G, AA$2, 'PPA 사업(C)'!$Q:$Q, $J3, 'PPA 사업(C)'!$C:$C, $L$1), COUNTIFS('리스사업(D)'!$G:$G, AA$2, '리스사업(D)'!$Q:$Q, $J3, '리스사업(D)'!$C:$C, $L$1), COUNTIFS('임대사업(E)'!$G:$G, AA$2, '임대사업(E)'!$Q:$Q, $J3, '임대사업(E)'!$C:$C, $L$1), COUNTIFS('환경부사업(F)'!$G:$G, AA$2, '환경부사업(F)'!$Q:$Q, $J3, '환경부사업(F)'!$C:$C, $L$1), COUNTIFS('프로젝트(G)'!$G:$G, AA$2, '프로젝트(G)'!$Q:$Q, $J3, '프로젝트(G)'!$C:$C, $L$1), COUNTIFS('협력사 EPC(H)'!$G:$G, AA$2, '협력사 EPC(H)'!$Q:$Q, $J3, '협력사 EPC(H)'!$C:$C, $L$1), COUNTIFS('기타(Z)'!$G:$G, AA$2, '기타(Z)'!$Q:$Q, $J3, '기타(Z)'!$C:$C, $L$1) ) = 0, "", COUNTIFS('발전사업(A)'!$G:$G, AA$2, '발전사업(A)'!$Q:$Q, $J3, '발전사업(A)'!$C:$C, $L$1) + COUNTIFS('자가소비(B)'!$G:$G, AA$2, '자가소비(B)'!$Q:$Q, $J3, '자가소비(B)'!$C:$C, $L$1) + COUNTIFS('PPA 사업(C)'!$G:$G, AA$2, 'PPA 사업(C)'!$Q:$Q, $J3, 'PPA 사업(C)'!$C:$C, $L$1) + COUNTIFS('리스사업(D)'!$G:$G, AA$2, '리스사업(D)'!$Q:$Q, $J3, '리스사업(D)'!$C:$C, $L$1) + COUNTIFS('임대사업(E)'!$G:$G, AA$2, '임대사업(E)'!$Q:$Q, $J3, '임대사업(E)'!$C:$C, $L$1) + COUNTIFS('환경부사업(F)'!$G:$G, AA$2, '환경부사업(F)'!$Q:$Q, $J3, '환경부사업(F)'!$C:$C, $L$1) + COUNTIFS('프로젝트(G)'!$G:$G, AA$2, '프로젝트(G)'!$Q:$Q, $J3, '프로젝트(G)'!$C:$C, $L$1) + COUNTIFS('협력사 EPC(H)'!$G:$G, AA$2, '협력사 EPC(H)'!$Q:$Q, $J3, '협력사 EPC(H)'!$C:$C, $L$1) + COUNTIFS('기타(Z)'!$G:$G, AA$2, '기타(Z)'!$Q:$Q, $J3, '기타(Z)'!$C:$C, $L$1) ) -> 3 | AC3: =IF( SUM( SUMIFS('발전사업(A)'!$I:$I,'발전사업(A)'!$G:$G,AC$2,'발전사업(A)'!$Q:$Q,$J3,'발전사업(A)'!$C:$C,$L$1), SUMIFS('자가소비(B)'!$I:$I,'자가소비(B)'!$G:$G,AC$2,'자가소비(B)'!$Q:$Q,$J3,'자가소비(B)'!$C:$C,$L$1), SUMIFS('PPA 사업(C)'!$I:$I,'PPA 사업(C)'!$G:$G,AC$2,'PPA 사업(C)'!$Q:$Q,$J3,'PPA 사업(C)'!$C:$C,$L$1), SUMIFS('리스사업(D)'!$I:$I,'리스사업(D)'!$G:$G,AC$2,'리스사업(D)'!$Q:$Q,$J3,'리스사업(D)'!$C:$C,$L$1), SUMIFS('임대사업(E)'!$I:$I,'임대사업(E)'!$G:$G,AC$2,'임대사업(E)'!$Q:$Q,$J3,'임대사업(E)'!$C:$C,$L$1), SUMIFS('환경부사업(F)'!$I:$I,'환경부사업(F)'!$G:$G,AC$2,'환경부사업(F)'!$Q:$Q,$J3,'환경부사업(F)'!$C:$C,$L$1), SUMIFS('프로젝트(G)'!$I:$I,'프로젝트(G)'!$G:$G,AC$2,'프로젝트(G)'!$Q:$Q,$J3,'프로젝트(G)'!$C:$C,$L$1), SUMIFS('협력사 EPC(H)'!$I:$I,'협력사 EPC(H)'!$G:$G,AC$2,'협력사 EPC(H)'!$Q:$Q,$J3,'협력사 EPC(H)'!$C:$C,$L$1), SUMIFS('기타(Z)'!$I:$I,'기타(Z)'!$G:$G,AC$2,'기타(Z)'!$Q:$Q,$J3,'기타(Z)'!$C:$C,$L$1) )=0, "", SUM( SUMIFS('발전사업(A)'!$I:$I,'발전사업(A)'!$G:$G,AC$2,'발전사업(A)'!$Q:$Q,$J3,'발전사업(A)'!$C:$C,$L$1), SUMIFS('자가소비(B)'!$I:$I,'자가소비(B)'!$G:$G,AC$2,'자가소비(B)'!$Q:$Q,$J3,'자가소비(B)'!$C:$C,$L$1), SUMIFS('PPA 사업(C)'!$I:$I,'PPA 사업(C)'!$G:$G,AC$2,'PPA 사업(C)'!$Q:$Q,$J3,'PPA 사업(C)'!$C:$C,$L$1), SUMIFS('리스사업(D)'!$I:$I,'리스사업(D)'!$G:$G,AC$2,'리스사업(D)'!$Q:$Q,$J3,'리스사업(D)'!$C:$C,$L$1), SUMIFS('임대사업(E)'!$I:$I,'임대사업(E)'!$G:$G,AC$2,'임대사업(E)'!$Q:$Q,$J3,'임대사업(E)'!$C:$C,$L$1), SUMIFS('환경부사업(F)'!$I:$I,'환경부사업(F)'!$G:$G,AC$2,'환경부사업(F)'!$Q:$Q,$J3,'환경부사업(F)'!$C:$C,$L$1), SUMIFS('프로젝트(G)'!$I:$I,'프로젝트(G)'!$G:$G,AC$2,'프로젝트(G)'!$Q:$Q,$J3,'프로젝트(G)'!$C:$C,$L$1), SUMIFS('협력사 EPC(H)'!$I:$I,'협력사 EPC(H)'!$G:$G,AC$2,'협력사 EPC(H)'!$Q:$Q,$J3,'협력사 EPC(H)'!$C:$C,$L$1), SUMIFS('기타(Z)'!$I:$I,'기타(Z)'!$G:$G,AC$2,'기타(Z)'!$Q:$Q,$J3,'기타(Z)'!$C:$C,$L$1) ) ) -> 1178.24 | AD3: =IF( SUM( COUNTIFS('발전사업(A)'!$G:$G, AC$2, '발전사업(A)'!$Q:$Q, $J3, '발전사업(A)'!$C:$C, $L$1), COUNTIFS('자가소비(B)'!$G:$G, AC$2, '자가소비(B)'!$Q:$Q, $J3, '자가소비(B)'!$C:$C, $L$1), COUNTIFS('PPA 사업(C)'!$G:$G, AC$2, 'PPA 사업(C)'!$Q:$Q, $J3, 'PPA 사업(C)'!$C:$C, $L$1), COUNTIFS('리스사업(D)'!$G:$G, AC$2, '리스사업(D)'!$Q:$Q, $J3, '리스사업(D)'!$C:$C, $L$1), COUNTIFS('임대사업(E)'!$G:$G, AC$2, '임대사업(E)'!$Q:$Q, $J3, '임대사업(E)'!$C:$C, $L$1), COUNTIFS('환경부사업(F)'!$G:$G, AC$2, '환경부사업(F)'!$Q:$Q, $J3, '환경부사업(F)'!$C:$C, $L$1), COUNTIFS('프로젝트(G)'!$G:$G, AC$2, '프로젝트(G)'!$Q:$Q, $J3, '프로젝트(G)'!$C:$C, $L$1), COUNTIFS('협력사 EPC(H)'!$G:$G, AC$2, '협력사 EPC(H)'!$Q:$Q, $J3, '협력사 EPC(H)'!$C:$C, $L$1), COUNTIFS('기타(Z)'!$G:$G, AC$2, '기타(Z)'!$Q:$Q, $J3, '기타(Z)'!$C:$C, $L$1) ) = 0, "", COUNTIFS('발전사업(A)'!$G:$G, AC$2, '발전사업(A)'!$Q:$Q, $J3, '발전사업(A)'!$C:$C, $L$1) + COUNTIFS('자가소비(B)'!$G:$G, AC$2, '자가소비(B)'!$Q:$Q, $J3, '자가소비(B)'!$C:$C, $L$1) + COUNTIFS('PPA 사업(C)'!$G:$G, AC$2, 'PPA 사업(C)'!$Q:$Q, $J3, 'PPA 사업(C)'!$C:$C, $L$1) + COUNTIFS('리스사업(D)'!$G:$G, AC$2, '리스사업(D)'!$Q:$Q, $J3, '리스사업(D)'!$C:$C, $L$1) + COUNTIFS('임대사업(E)'!$G:$G, AC$2, '임대사업(E)'!$Q:$Q, $J3, '임대사업(E)'!$C:$C, $L$1) + COUNTIFS('환경부사업(F)'!$G:$G, AC$2, '환경부사업(F)'!$Q:$Q, $J3, '환경부사업(F)'!$C:$C, $L$1) + COUNTIFS('프로젝트(G)'!$G:$G, AC$2, '프로젝트(G)'!$Q:$Q, $J3, '프로젝트(G)'!$C:$C, $L$1) + COUNTIFS('협력사 EPC(H)'!$G:$G, AC$2, '협력사 EPC(H)'!$Q:$Q, $J3, '협력사 EPC(H)'!$C:$C, $L$1) + COUNTIFS('기타(Z)'!$G:$G, AC$2, '기타(Z)'!$Q:$Q, $J3, '기타(Z)'!$C:$C, $L$1) ) -> 7 | AE3: =IF( SUM( SUMIFS('발전사업(A)'!$I:$I,'발전사업(A)'!$G:$G,AE$2,'발전사업(A)'!$Q:$Q,$J3,'발전사업(A)'!$C:$C,$L$1), SUMIFS('자가소비(B)'!$I:$I,'자가소비(B)'!$G:$G,AE$2,'자가소비(B)'!$Q:$Q,$J3,'자가소비(B)'!$C:$C,$L$1), SUMIFS('PPA 사업(C)'!$I:$I,'PPA 사업(C)'!$G:$G,AE$2,'PPA 사업(C)'!$Q:$Q,$J3,'PPA 사업(C)'!$C:$C,$L$1), SUMIFS('리스사업(D)'!$I:$I,'리스사업(D)'!$G:$G,AE$2,'리스사업(D)'!$Q:$Q,$J3,'리스사업(D)'!$C:$C,$L$1), SUMIFS('임대사업(E)'!$I:$I,'임대사업(E)'!$G:$G,AE$2,'임대사업(E)'!$Q:$Q,$J3,'임대사업(E)'!$C:$C,$L$1), SUMIFS('환경부사업(F)'!$I:$I,'환경부사업(F)'!$G:$G,AE$2,'환경부사업(F)'!$Q:$Q,$J3,'환경부사업(F)'!$C:$C,$L$1), SUMIFS('프로젝트(G)'!$I:$I,'프로젝트(G)'!$G:$G,AE$2,'프로젝트(G)'!$Q:$Q,$J3,'프로젝트(G)'!$C:$C,$L$1), SUMIFS('협력사 EPC(H)'!$I:$I,'협력사 EPC(H)'!$G:$G,AE$2,'협력사 EPC(H)'!$Q:$Q,$J3,'협력사 EPC(H)'!$C:$C,$L$1), SUMIFS('기타(Z)'!$I:$I,'기타(Z)'!$G:$G,AE$2,'기타(Z)'!$Q:$Q,$J3,'기타(Z)'!$C:$C,$L$1) )=0, "", SUM( SUMIFS('발전사업(A)'!$I:$I,'발전사업(A)'!$G:$G,AE$2,'발전사업(A)'!$Q:$Q,$J3,'발전사업(A)'!$C:$C,$L$1), SUMIFS('자가소비(B)'!$I:$I,'자가소비(B)'!$G:$G,AE$2,'자가소비(B)'!$Q:$Q,$J3,'자가소비(B)'!$C:$C,$L$1), SUMIFS('PPA 사업(C)'!$I:$I,'PPA 사업(C)'!$G:$G,AE$2,'PPA 사업(C)'!$Q:$Q,$J3,'PPA 사업(C)'!$C:$C,$L$1), SUMIFS('리스사업(D)'!$I:$I,'리스사업(D)'!$G:$G,AE$2,'리스사업(D)'!$Q:$Q,$J3,'리스사업(D)'!$C:$C,$L$1), SUMIFS('임대사업(E)'!$I:$I,'임대사업(E)'!$G:$G,AE$2,'임대사업(E)'!$Q:$Q,$J3,'임대사업(E)'!$C:$C,$L$1), SUMIFS('환경부사업(F)'!$I:$I,'환경부사업(F)'!$G:$G,AE$2,'환경부사업(F)'!$Q:$Q,$J3,'환경부사업(F)'!$C:$C,$L$1), SUMIFS('프로젝트(G)'!$I:$I,'프로젝트(G)'!$G:$G,AE$2,'프로젝트(G)'!$Q:$Q,$J3,'프로젝트(G)'!$C:$C,$L$1), SUMIFS('협력사 EPC(H)'!$I:$I,'협력사 EPC(H)'!$G:$G,AE$2,'협력사 EPC(H)'!$Q:$Q,$J3,'협력사 EPC(H)'!$C:$C,$L$1), SUMIFS('기타(Z)'!$I:$I,'기타(Z)'!$G:$G,AE$2,'기타(Z)'!$Q:$Q,$J3,'기타(Z)'!$C:$C,$L$1) ) ) -> 767.36 | AF3: =IF( SUM( COUNTIFS('발전사업(A)'!$G:$G, AE$2, '발전사업(A)'!$Q:$Q, $J3, '발전사업(A)'!$C:$C, $L$1), COUNTIFS('자가소비(B)'!$G:$G, AE$2, '자가소비(B)'!$Q:$Q, $J3, '자가소비(B)'!$C:$C, $L$1), COUNTIFS('PPA 사업(C)'!$G:$G, AE$2, 'PPA 사업(C)'!$Q:$Q, $J3, 'PPA 사업(C)'!$C:$C, $L$1), COUNTIFS('리스사업(D)'!$G:$G, AE$2, '리스사업(D)'!$Q:$Q, $J3, '리스사업(D)'!$C:$C, $L$1), COUNTIFS('임대사업(E)'!$G:$G, AE$2, '임대사업(E)'!$Q:$Q, $J3, '임대사업(E)'!$C:$C, $L$1), COUNTIFS('환경부사업(F)'!$G:$G, AE$2, '환경부사업(F)'!$Q:$Q, $J3, '환경부사업(F)'!$C:$C, $L$1), COUNTIFS('프로젝트(G)'!$G:$G, AE$2, '프로젝트(G)'!$Q:$Q, $J3, '프로젝트(G)'!$C:$C, $L$1), COUNTIFS('협력사 EPC(H)'!$G:$G, AE$2, '협력사 EPC(H)'!$Q:$Q, $J3, '협력사 EPC(H)'!$C:$C, $L$1), COUNTIFS('기타(Z)'!$G:$G, AE$2, '기타(Z)'!$Q:$Q, $J3, '기타(Z)'!$C:$C, $L$1) ) = 0, "", COUNTIFS('발전사업(A)'!$G:$G, AE$2, '발전사업(A)'!$Q:$Q, $J3, '발전사업(A)'!$C:$C, $L$1) + COUNTIFS('자가소비(B)'!$G:$G, AE$2, '자가소비(B)'!$Q:$Q, $J3, '자가소비(B)'!$C:$C, $L$1) + COUNTIFS('PPA 사업(C)'!$G:$G, AE$2, 'PPA 사업(C)'!$Q:$Q, $J3, 'PPA 사업(C)'!$C:$C, $L$1) + COUNTIFS('리스사업(D)'!$G:$G, AE$2, '리스사업(D)'!$Q:$Q, $J3, '리스사업(D)'!$C:$C, $L$1) + COUNTIFS('임대사업(E)'!$G:$G, AE$2, '임대사업(E)'!$Q:$Q, $J3, '임대사업(E)'!$C:$C, $L$1) + COUNTIFS('환경부사업(F)'!$G:$G, AE$2, '환경부사업(F)'!$Q:$Q, $J3, '환경부사업(F)'!$C:$C, $L$1) + COUNTIFS('프로젝트(G)'!$G:$G, AE$2, '프로젝트(G)'!$Q:$Q, $J3, '프로젝트(G)'!$C:$C, $L$1) + COUNTIFS('협력사 EPC(H)'!$G:$G, AE$2, '협력사 EPC(H)'!$Q:$Q, $J3, '협력사 EPC(H)'!$C:$C, $L$1) + COUNTIFS('기타(Z)'!$G:$G, AE$2, '기타(Z)'!$Q:$Q, $J3, '기타(Z)'!$C:$C, $L$1) ) -> 6 | AG3: =IF( SUM( SUMIFS('발전사업(A)'!$I:$I,'발전사업(A)'!$G:$G,AG$2,'발전사업(A)'!$Q:$Q,$J3,'발전사업(A)'!$C:$C,$L$1), SUMIFS('자가소비(B)'!$I:$I,'자가소비(B)'!$G:$G,AG$2,'자가소비(B)'!$Q:$Q,$J3,'자가소비(B)'!$C:$C,$L$1), SUMIFS('PPA 사업(C)'!$I:$I,'PPA 사업(C)'!$G:$G,AG$2,'PPA 사업(C)'!$Q:$Q,$J3,'PPA 사업(C)'!$C:$C,$L$1), SUMIFS('리스사업(D)'!$I:$I,'리스사업(D)'!$G:$G,AG$2,'리스사업(D)'!$Q:$Q,$J3,'리스사업(D)'!$C:$C,$L$1), SUMIFS('임대사업(E)'!$I:$I,'임대사업(E)'!$G:$G,AG$2,'임대사업(E)'!$Q:$Q,$J3,'임대사업(E)'!$C:$C,$L$1), SUMIFS('환경부사업(F)'!$I:$I,'환경부사업(F)'!$G:$G,AG$2,'환경부사업(F)'!$Q:$Q,$J3,'환경부사업(F)'!$C:$C,$L$1), SUMIFS('프로젝트(G)'!$I:$I,'프로젝트(G)'!$G:$G,AG$2,'프로젝트(G)'!$Q:$Q,$J3,'프로젝트(G)'!$C:$C,$L$1), SUMIFS('협력사 EPC(H)'!$I:$I,'협력사 EPC(H)'!$G:$G,AG$2,'협력사 EPC(H)'!$Q:$Q,$J3,'협력사 EPC(H)'!$C:$C,$L$1), SUMIFS('기타(Z)'!$I:$I,'기타(Z)'!$G:$G,AG$2,'기타(Z)'!$Q:$Q,$J3,'기타(Z)'!$C:$C,$L$1) )=0, "", SUM( SUMIFS('발전사업(A)'!$I:$I,'발전사업(A)'!$G:$G,AG$2,'발전사업(A)'!$Q:$Q,$J3,'발전사업(A)'!$C:$C,$L$1), SUMIFS('자가소비(B)'!$I:$I,'자가소비(B)'!$G:$G,AG$2,'자가소비(B)'!$Q:$Q,$J3,'자가소비(B)'!$C:$C,$L$1), SUMIFS('PPA 사업(C)'!$I:$I,'PPA 사업(C)'!$G:$G,AG$2,'PPA 사업(C)'!$Q:$Q,$J3,'PPA 사업(C)'!$C:$C,$L$1), SUMIFS('리스사업(D)'!$I:$I,'리스사업(D)'!$G:$G,AG$2,'리스사업(D)'!$Q:$Q,$J3,'리스사업(D)'!$C:$C,$L$1), SUMIFS('임대사업(E)'!$I:$I,'임대사업(E)'!$G:$G,AG$2,'임대사업(E)'!$Q:$Q,$J3,'임대사업(E)'!$C:$C,$L$1), SUMIFS('환경부사업(F)'!$I:$I,'환경부사업(F)'!$G:$G,AG$2,'환경부사업(F)'!$Q:$Q,$J3,'환경부사업(F)'!$C:$C,$L$1), SUMIFS('프로젝트(G)'!$I:$I,'프로젝트(G)'!$G:$G,AG$2,'프로젝트(G)'!$Q:$Q,$J3,'프로젝트(G)'!$C:$C,$L$1), SUMIFS('협력사 EPC(H)'!$I:$I,'협력사 EPC(H)'!$G:$G,AG$2,'협력사 EPC(H)'!$Q:$Q,$J3,'협력사 EPC(H)'!$C:$C,$L$1), SUMIFS('기타(Z)'!$I:$I,'기타(Z)'!$G:$G,AG$2,'기타(Z)'!$Q:$Q,$J3,'기타(Z)'!$C:$C,$L$1) ) ) -> 1575.09 | AH3: =IF( SUM( COUNTIFS('발전사업(A)'!$G:$G, AG$2, '발전사업(A)'!$Q:$Q, $J3, '발전사업(A)'!$C:$C, $L$1), COUNTIFS('자가소비(B)'!$G:$G, AG$2, '자가소비(B)'!$Q:$Q, $J3, '자가소비(B)'!$C:$C, $L$1), COUNTIFS('PPA 사업(C)'!$G:$G, AG$2, 'PPA 사업(C)'!$Q:$Q, $J3, 'PPA 사업(C)'!$C:$C, $L$1), COUNTIFS('리스사업(D)'!$G:$G, AG$2, '리스사업(D)'!$Q:$Q, $J3, '리스사업(D)'!$C:$C, $L$1), COUNTIFS('임대사업(E)'!$G:$G, AG$2, '임대사업(E)'!$Q:$Q, $J3, '임대사업(E)'!$C:$C, $L$1), COUNTIFS('환경부사업(F)'!$G:$G, AG$2, '환경부사업(F)'!$Q:$Q, $J3, '환경부사업(F)'!$C:$C, $L$1), COUNTIFS('프로젝트(G)'!$G:$G, AG$2, '프로젝트(G)'!$Q:$Q, $J3, '프로젝트(G)'!$C:$C, $L$1), COUNTIFS('협력사 EPC(H)'!$G:$G, AG$2, '협력사 EPC(H)'!$Q:$Q, $J3, '협력사 EPC(H)'!$C:$C, $L$1), COUNTIFS('기타(Z)'!$G:$G, AG$2, '기타(Z)'!$Q:$Q, $J3, '기타(Z)'!$C:$C, $L$1) ) = 0, "", COUNTIFS('발전사업(A)'!$G:$G, AG$2, '발전사업(A)'!$Q:$Q, $J3, '발전사업(A)'!$C:$C, $L$1) + COUNTIFS('자가소비(B)'!$G:$G, AG$2, '자가소비(B)'!$Q:$Q, $J3, '자가소비(B)'!$C:$C, $L$1) + COUNTIFS('PPA 사업(C)'!$G:$G, AG$2, 'PPA 사업(C)'!$Q:$Q, $J3, 'PPA 사업(C)'!$C:$C, $L$1) + COUNTIFS('리스사업(D)'!$G:$G, AG$2, '리스사업(D)'!$Q:$Q, $J3, '리스사업(D)'!$C:$C, $L$1) + COUNTIFS('임대사업(E)'!$G:$G, AG$2, '임대사업(E)'!$Q:$Q, $J3, '임대사업(E)'!$C:$C, $L$1) + COUNTIFS('환경부사업(F)'!$G:$G, AG$2, '환경부사업(F)'!$Q:$Q, $J3, '환경부사업(F)'!$C:$C, $L$1) + COUNTIFS('프로젝트(G)'!$G:$G, AG$2, '프로젝트(G)'!$Q:$Q, $J3, '프로젝트(G)'!$C:$C, $L$1) + COUNTIFS('협력사 EPC(H)'!$G:$G, AG$2, '협력사 EPC(H)'!$Q:$Q, $J3, '협력사 EPC(H)'!$C:$C, $L$1) + COUNTIFS('기타(Z)'!$G:$G, AG$2, '기타(Z)'!$Q:$Q, $J3, '기타(Z)'!$C:$C, $L$1) ) -> 6 | AI3: =IF( SUM( SUMIFS('발전사업(A)'!$I:$I,'발전사업(A)'!$G:$G,AI$2,'발전사업(A)'!$Q:$Q,$J3,'발전사업(A)'!$C:$C,$L$1), SUMIFS('자가소비(B)'!$I:$I,'자가소비(B)'!$G:$G,AI$2,'자가소비(B)'!$Q:$Q,$J3,'자가소비(B)'!$C:$C,$L$1), SUMIFS('PPA 사업(C)'!$I:$I,'PPA 사업(C)'!$G:$G,AI$2,'PPA 사업(C)'!$Q:$Q,$J3,'PPA 사업(C)'!$C:$C,$L$1), SUMIFS('리스사업(D)'!$I:$I,'리스사업(D)'!$G:$G,AI$2,'리스사업(D)'!$Q:$Q,$J3,'리스사업(D)'!$C:$C,$L$1), SUMIFS('임대사업(E)'!$I:$I,'임대사업(E)'!$G:$G,AI$2,'임대사업(E)'!$Q:$Q,$J3,'임대사업(E)'!$C:$C,$L$1), SUMIFS('환경부사업(F)'!$I:$I,'환경부사업(F)'!$G:$G,AI$2,'환경부사업(F)'!$Q:$Q,$J3,'환경부사업(F)'!$C:$C,$L$1), SUMIFS('프로젝트(G)'!$I:$I,'프로젝트(G)'!$G:$G,AI$2,'프로젝트(G)'!$Q:$Q,$J3,'프로젝트(G)'!$C:$C,$L$1), SUMIFS('협력사 EPC(H)'!$I:$I,'협력사 EPC(H)'!$G:$G,AI$2,'협력사 EPC(H)'!$Q:$Q,$J3,'협력사 EPC(H)'!$C:$C,$L$1), SUMIFS('기타(Z)'!$I:$I,'기타(Z)'!$G:$G,AI$2,'기타(Z)'!$Q:$Q,$J3,'기타(Z)'!$C:$C,$L$1) )=0, "", SUM( SUMIFS('발전사업(A)'!$I:$I,'발전사업(A)'!$G:$G,AI$2,'발전사업(A)'!$Q:$Q,$J3,'발전사업(A)'!$C:$C,$L$1), SUMIFS('자가소비(B)'!$I:$I,'자가소비(B)'!$G:$G,AI$2,'자가소비(B)'!$Q:$Q,$J3,'자가소비(B)'!$C:$C,$L$1), SUMIFS('PPA 사업(C)'!$I:$I,'PPA 사업(C)'!$G:$G,AI$2,'PPA 사업(C)'!$Q:$Q,$J3,'PPA 사업(C)'!$C:$C,$L$1), SUMIFS('리스사업(D)'!$I:$I,'리스사업(D)'!$G:$G,AI$2,'리스사업(D)'!$Q:$Q,$J3,'리스사업(D)'!$C:$C,$L$1), SUMIFS('임대사업(E)'!$I:$I,'임대사업(E)'!$G:$G,AI$2,'임대사업(E)'!$Q:$Q,$J3,'임대사업(E)'!$C:$C,$L$1), SUMIFS('환경부사업(F)'!$I:$I,'환경부사업(F)'!$G:$G,AI$2,'환경부사업(F)'!$Q:$Q,$J3,'환경부사업(F)'!$C:$C,$L$1), SUMIFS('프로젝트(G)'!$I:$I,'프로젝트(G)'!$G:$G,AI$2,'프로젝트(G)'!$Q:$Q,$J3,'프로젝트(G)'!$C:$C,$L$1), SUMIFS('협력사 EPC(H)'!$I:$I,'협력사 EPC(H)'!$G:$G,AI$2,'협력사 EPC(H)'!$Q:$Q,$J3,'협력사 EPC(H)'!$C:$C,$L$1), SUMIFS('기타(Z)'!$I:$I,'기타(Z)'!$G:$G,AI$2,'기타(Z)'!$Q:$Q,$J3,'기타(Z)'!$C:$C,$L$1) ) ) -> 1545.42 | AJ3: =IF( SUM( COUNTIFS('발전사업(A)'!$G:$G, AI$2, '발전사업(A)'!$Q:$Q, $J3, '발전사업(A)'!$C:$C, $L$1), COUNTIFS('자가소비(B)'!$G:$G, AI$2, '자가소비(B)'!$Q:$Q, $J3, '자가소비(B)'!$C:$C, $L$1), COUNTIFS('PPA 사업(C)'!$G:$G, AI$2, 'PPA 사업(C)'!$Q:$Q, $J3, 'PPA 사업(C)'!$C:$C, $L$1), COUNTIFS('리스사업(D)'!$G:$G, AI$2, '리스사업(D)'!$Q:$Q, $J3, '리스사업(D)'!$C:$C, $L$1), COUNTIFS('임대사업(E)'!$G:$G, AI$2, '임대사업(E)'!$Q:$Q, $J3, '임대사업(E)'!$C:$C, $L$1), COUNTIFS('환경부사업(F)'!$G:$G, AI$2, '환경부사업(F)'!$Q:$Q, $J3, '환경부사업(F)'!$C:$C, $L$1), COUNTIFS('프로젝트(G)'!$G:$G, AI$2, '프로젝트(G)'!$Q:$Q, $J3, '프로젝트(G)'!$C:$C, $L$1), COUNTIFS('협력사 EPC(H)'!$G:$G, AI$2, '협력사 EPC(H)'!$Q:$Q, $J3, '협력사 EPC(H)'!$C:$C, $L$1), COUNTIFS('기타(Z)'!$G:$G, AI$2, '기타(Z)'!$Q:$Q, $J3, '기타(Z)'!$C:$C, $L$1) ) = 0, "", COUNTIFS('발전사업(A)'!$G:$G, AI$2, '발전사업(A)'!$Q:$Q, $J3, '발전사업(A)'!$C:$C, $L$1) + COUNTIFS('자가소비(B)'!$G:$G, AI$2, '자가소비(B)'!$Q:$Q, $J3, '자가소비(B)'!$C:$C, $L$1) + COUNTIFS('PPA 사업(C)'!$G:$G, AI$2, 'PPA 사업(C)'!$Q:$Q, $J3, 'PPA 사업(C)'!$C:$C, $L$1) + COUNTIFS('리스사업(D)'!$G:$G, AI$2, '리스사업(D)'!$Q:$Q, $J3, '리스사업(D)'!$C:$C, $L$1) + COUNTIFS('임대사업(E)'!$G:$G, AI$2, '임대사업(E)'!$Q:$Q, $J3, '임대사업(E)'!$C:$C, $L$1) + COUNTIFS('환경부사업(F)'!$G:$G, AI$2, '환경부사업(F)'!$Q:$Q, $J3, '환경부사업(F)'!$C:$C, $L$1) + COUNTIFS('프로젝트(G)'!$G:$G, AI$2, '프로젝트(G)'!$Q:$Q, $J3, '프로젝트(G)'!$C:$C, $L$1) + COUNTIFS('협력사 EPC(H)'!$G:$G, AI$2, '협력사 EPC(H)'!$Q:$Q, $J3, '협력사 EPC(H)'!$C:$C, $L$1) + COUNTIFS('기타(Z)'!$G:$G, AI$2, '기타(Z)'!$Q:$Q, $J3, '기타(Z)'!$C:$C, $L$1) ) -> 5
